Using 16bit Automatic Mixed Precision (AMP)
GPU available: True (cuda), used: True
TPU available: False, using: 0 TPU cores
HPU available: False, using: 0 HPUs
You are using a CUDA device ('NVIDIA A800-SXM4-80GB') that has Tensor Cores. To properly utilize them, you should set `torch.set_float32_matmul_precision('medium' | 'high')` which will trade-off precision for performance. For more details, read https://pytorch.org/docs/stable/generated/torch.set_float32_matmul_precision.html#torch.set_float32_matmul_precision
Using 26969/269695 training samples (10.0%)
LOCAL_RANK: 0 - CUDA_VISIBLE_DEVICES: [0,1]
/hpc2hdd/home/qwang650/anaconda3/envs/caco/lib/python3.10/site-packages/pytorch_lightning/utilities/model_summary/model_summary.py:231: Precision 16-mixed is not supported by the model summary.  Estimated model size in MB will not be accurate. Using 32 bits instead.

   | Name            | Type                | Params | Mode
-----------------------------------------------------------------
0  | backbone        | Sequential          | 23.5 M | train
1  | classifier      | Sequential          | 38.9 K | train
2  | criterion       | BCEWithLogitsLoss   | 0      | train
3  | train_precision | MultilabelPrecision | 0      | train
4  | train_recall    | MultilabelRecall    | 0      | train
5  | train_f1        | MultilabelF1Score   | 0      | train
6  | train_auroc     | MultilabelAUROC     | 0      | train
7  | val_precision   | MultilabelPrecision | 0      | train
8  | val_recall      | MultilabelRecall    | 0      | train
9  | val_f1          | MultilabelF1Score   | 0      | train
10 | val_auroc       | MultilabelAUROC     | 0      | train
-----------------------------------------------------------------
38.9 K    Trainable params
23.5 M    Non-trainable params
23.5 M    Total params
94.188    Total estimated model params size (MB)
163       Modules in train mode
0         Modules in eval mode
Epoch 0:   0%|                                                                                        | 0/842 [00:00<?, ?it/s]
/hpc2hdd/home/qwang650/anaconda3/envs/caco/lib/python3.10/site-packages/torchmetrics/utilities/prints.py:43: UserWarning: No positive samples in targets, true positive value should be meaningless. Returning zero tensor in true positive score
  warnings.warn(*args, **kwargs)
/hpc2hdd/home/qwang650/anaconda3/envs/caco/lib/python3.10/site-packages/torchmetrics/utilities/prints.py:43: UserWarning: No negative samples in targets, false positive value should be meaningless. Returning zero tensor in false positive score
  warnings.warn(*args, **kwargs)
Traceback (most recent call last):
  File "/hpc2hdd/home/qwang650/project/yutianjiang/stmodel/models/baselines/CACo/src/main_bigearthnet.py", line 206, in <module>
    trainer.fit(model, datamodule=datamodule)
  File "/hpc2hdd/home/qwang650/anaconda3/envs/caco/lib/python3.10/site-packages/pytorch_lightning/trainer/trainer.py", line 560, in fit
    call._call_and_handle_interrupt(
  File "/hpc2hdd/home/qwang650/anaconda3/envs/caco/lib/python3.10/site-packages/pytorch_lightning/trainer/call.py", line 49, in _call_and_handle_interrupt
    return trainer_fn(*args, **kwargs)
  File "/hpc2hdd/home/qwang650/anaconda3/envs/caco/lib/python3.10/site-packages/pytorch_lightning/trainer/trainer.py", line 598, in _fit_impl
    self._run(model, ckpt_path=ckpt_path)
  File "/hpc2hdd/home/qwang650/anaconda3/envs/caco/lib/python3.10/site-packages/pytorch_lightning/trainer/trainer.py", line 1011, in _run
    results = self._run_stage()
  File "/hpc2hdd/home/qwang650/anaconda3/envs/caco/lib/python3.10/site-packages/pytorch_lightning/trainer/trainer.py", line 1055, in _run_stage
    self.fit_loop.run()
  File "/hpc2hdd/home/qwang650/anaconda3/envs/caco/lib/python3.10/site-packages/pytorch_lightning/loops/fit_loop.py", line 216, in run
    self.advance()
  File "/hpc2hdd/home/qwang650/anaconda3/envs/caco/lib/python3.10/site-packages/pytorch_lightning/loops/fit_loop.py", line 458, in advance
    self.epoch_loop.run(self._data_fetcher)
  File "/hpc2hdd/home/qwang650/anaconda3/envs/caco/lib/python3.10/site-packages/pytorch_lightning/loops/training_epoch_loop.py", line 152, in run
    self.advance(data_fetcher)
  File "/hpc2hdd/home/qwang650/anaconda3/envs/caco/lib/python3.10/site-packages/pytorch_lightning/loops/training_epoch_loop.py", line 310, in advance
    batch, _, __ = next(data_fetcher)
  File "/hpc2hdd/home/qwang650/anaconda3/envs/caco/lib/python3.10/site-packages/pytorch_lightning/loops/fetchers.py", line 134, in __next__
    batch = super().__next__()
  File "/hpc2hdd/home/qwang650/anaconda3/envs/caco/lib/python3.10/site-packages/pytorch_lightning/loops/fetchers.py", line 61, in __next__
    batch = next(self.iterator)
  File "/hpc2hdd/home/qwang650/anaconda3/envs/caco/lib/python3.10/site-packages/pytorch_lightning/utilities/combined_loader.py", line 341, in __next__
    out = next(self._iterator)
  File "/hpc2hdd/home/qwang650/anaconda3/envs/caco/lib/python3.10/site-packages/pytorch_lightning/utilities/combined_loader.py", line 78, in __next__
    out[i] = next(self.iterators[i])
  File "/hpc2hdd/home/qwang650/anaconda3/envs/caco/lib/python3.10/site-packages/torch/utils/data/dataloader.py", line 631, in __next__
    data = self._next_data()
  File "/hpc2hdd/home/qwang650/anaconda3/envs/caco/lib/python3.10/site-packages/torch/utils/data/dataloader.py", line 1346, in _next_data
    return self._process_data(data)
  File "/hpc2hdd/home/qwang650/anaconda3/envs/caco/lib/python3.10/site-packages/torch/utils/data/dataloader.py", line 1372, in _process_data
    data.reraise()
  File "/hpc2hdd/home/qwang650/anaconda3/envs/caco/lib/python3.10/site-packages/torch/_utils.py", line 705, in reraise
    raise exception
TypeError: Caught TypeError in DataLoader worker process 0.
Original Traceback (most recent call last):
  File "/hpc2hdd/home/qwang650/anaconda3/envs/caco/lib/python3.10/site-packages/torch/utils/data/_utils/worker.py", line 308, in _worker_loop
    data = fetcher.fetch(index)  # type: ignore[possibly-undefined]
  File "/hpc2hdd/home/qwang650/anaconda3/envs/caco/lib/python3.10/site-packages/torch/utils/data/_utils/fetch.py", line 49, in fetch
    data = self.dataset.__getitems__(possibly_batched_index)
  File "/hpc2hdd/home/qwang650/anaconda3/envs/caco/lib/python3.10/site-packages/torch/utils/data/dataset.py", line 419, in __getitems__
    return [self.dataset[self.indices[idx]] for idx in indices]
  File "/hpc2hdd/home/qwang650/anaconda3/envs/caco/lib/python3.10/site-packages/torch/utils/data/dataset.py", line 419, in <listcomp>
    return [self.dataset[self.indices[idx]] for idx in indices]
  File "/hpc2hdd/home/qwang650/project/yutianjiang/stmodel/models/baselines/CACo/src/ft_datasets/bigearthnet_hf_dataset.py", line 43, in __getitem__
    sample = self.dataset[index]
  File "/hpc2hdd/home/qwang650/anaconda3/envs/caco/lib/python3.10/site-packages/datasets/arrow_dataset.py", line 2862, in __getitem__
    return self._getitem(key)
  File "/hpc2hdd/home/qwang650/anaconda3/envs/caco/lib/python3.10/site-packages/datasets/arrow_dataset.py", line 2843, in _getitem
    pa_subtable = query_table(self._data, key, indices=self._indices)
  File "/hpc2hdd/home/qwang650/anaconda3/envs/caco/lib/python3.10/site-packages/datasets/formatting/formatting.py", line 612, in query_table
    _check_valid_index_key(key, size)
  File "/hpc2hdd/home/qwang650/anaconda3/envs/caco/lib/python3.10/site-packages/datasets/formatting/formatting.py", line 561, in _check_valid_index_key
    if len(key) > 0:
  File "/hpc2hdd/home/qwang650/anaconda3/envs/caco/lib/python3.10/site-packages/torch/_tensor.py", line 1025, in __len__
    raise TypeError("len() of a 0-d tensor")
TypeError: len() of a 0-d tensor
